2025-02-25 11:52:21,501 - ERROR - test.py:36 - Ocorreu um erro ao executar a tarefa.
Traceback (most recent call last):
  File "c:\Users\Nicolas\Desktop\TrabalhoCompass\test_api\test.py", line 33, in executar_tarefa
    resultado = 10 / 0  # Simulação de erro
                ~~~^~~
ZeroDivisionError: division by zero
2025-02-25 11:52:21,645 - ERROR - test03.py:142 - Erro ao preencher tabela de saída: 'NoneType' object does not support item assignment
